<?xml version="1.0" ?>
<robot name="roas">
  <material name="Black">
    <color rgba="0.00392156862745098 0.00392156862745098 0.00392156862745098 1.0"/>
  </material>
  <material name="dark_grey">
    <color rgba="0.2 0.2 0.2 1.0"/>
  </material>
  <!-- Base link -->
  <link name="base_link">
    <visual>
      <origin rpy="0 0 0" xyz="0 0 0"/>
      <geometry>
       <!--  <mesh filename="/home/hycon/gazebo_nav2/scout_bot_description/meshes/include/base_link.dae"/> -->
         <box size="0.925 0.38 0.21"/>
      </geometry>
    </visual>
    <collision>
      <origin rpy="0 0 0" xyz="0 0 0.008"/>
      <geometry>
        <box size="0.925 0.38 0.21"/>
      </geometry>
    </collision>
    <collision>
      <origin rpy="0 0 0" xyz="0 0 0.034999999999999996"/>
      <geometry>
        <box size="0.15416666666666667 0.627 0.06999999999999999"/>
      </geometry>
    </collision>
  </link>
  <link name="base_footprint"/>
  <joint name="base_footprint_joint" type="fixed">
    <origin rpy="0 0 0" xyz="0 0 -0.23479"/>
    <parent link="base_link"/>
    <child link="base_footprint"/>
  </joint>
  <link name="inertial_link">
    <inertial>
      <mass value="40"/>
      <origin xyz="0.0 0.0 0.0"/>
      <inertia ixx="2.288641" ixy="0" ixz="0" iyy="5.103976" iyz="0" izz="3.431465"/>
    </inertial>
  </link>
  <joint name="inertial_joint" type="fixed">
    <origin rpy="0 0 0" xyz="0 0 0"/>
    <parent link="base_link"/>
    <child link="inertial_link"/>
  </joint>
  <link name="front_right_wheel_link">
    <inertial>
      <mass value="3"/>
      <origin xyz="0 0 0"/>
      <inertia ixx="0.7171" ixy="0" ixz="0" iyy="0.1361" iyz="0" izz="0.7171"/>
    </inertial>
    <visual>
      <origin rpy="-1.570795 0 0" xyz="0 0 0"/>
      <geometry>
<!--         <mesh filename="package://scout_bot_description/meshes/include/wheel_type1.dae"/>-->
         <cylinder radius="0.16459" length="0.11653"/>
      </geometry>
    </visual>
    <collision>
      <origin rpy="-1.570795 0 0" xyz="0 0 0"/>
      <geometry>
        <cylinder length="0.11653" radius="0.16459"/>
      </geometry>
    </collision>
  </link>
  <joint name="front_right_wheel" type="continuous">
    <parent link="base_link"/>
    <child link="front_right_wheel_link"/>
    <origin rpy="0 0 0" xyz="0.249 -0.29153 -0.0702"/>
    <axis rpy="0 0 0" xyz="0 1 0"/>
  </joint>
  <link name="front_left_wheel_link">
    <inertial>
      <mass value="3"/>
      <origin xyz="0 0 0"/>
      <inertia ixx="0.7171" ixy="0" ixz="0" iyy="0.1361" iyz="0" izz="0.7171"/>
    </inertial>
    <visual>
      <origin rpy="1.570795 0 0" xyz="0 0 0"/>
      <geometry>
        <!-- <mesh filename="package://scout_bot_description/meshes/include/wheel_type2.dae"/> -->
         <cylinder radius="0.16459" length="0.11653"/>
      </geometry>
    </visual>
    <collision>
      <origin rpy="1.570795 0 0" xyz="0 0 0"/>
      <geometry>
        <cylinder length="0.11653" radius="0.16459"/>
      </geometry>
    </collision>
  </link>
  <joint name="front_left_wheel" type="continuous">
    <parent link="base_link"/>
    <child link="front_left_wheel_link"/>
    <origin rpy="0 0 0" xyz="0.249 0.29153 -0.0702"/>
    <axis rpy="0 0 0" xyz="0 1 0"/>
  </joint>
  <link name="rear_left_wheel_link">
    <inertial>
      <mass value="3"/>
      <origin xyz="0 0 0"/>
      <inertia ixx="0.7171" ixy="0" ixz="0" iyy="0.1361" iyz="0" izz="0.7171"/>
    </inertial>
    <visual>
      <origin rpy="1.570795 0 0" xyz="0 0 0"/>
      <geometry>
        <!-- <mesh filename="package://scout_bot_description/meshes/include/wheel_type1.dae"/> -->
        <cylinder radius="0.16459" length="0.11653"/>
      </geometry>
    </visual>
    <collision>
      <origin rpy="1.570795 0 0" xyz="0 0 0"/>
      <geometry>
        <cylinder length="0.11653" radius="0.16459"/>
      </geometry>
    </collision>
  </link>
  <joint name="rear_left_wheel" type="continuous">
    <parent link="base_link"/>
    <child link="rear_left_wheel_link"/>
    <origin rpy="0 0 0" xyz="-0.249 0.29153 -0.0702"/>
    <axis rpy="0 0 0" xyz="0 1 0"/>
  </joint>
  <link name="rear_right_wheel_link">
    <inertial>
      <mass value="3"/>
      <origin xyz="0 0 0"/>
      <inertia ixx="0.7171" ixy="0" ixz="0" iyy="0.1361" iyz="0" izz="0.7171"/>
    </inertial>
    <visual>
      <origin rpy="-1.570795 0 0" xyz="0 0 0"/>
      <geometry>
        <!-- <mesh filename="package://scout_bot_description/meshes/include/wheel_type2.dae"/> -->
        <cylinder radius="0.16459" length="0.11653"/>
      </geometry>
    </visual>
    <collision>
      <origin rpy="-1.570795 0 0" xyz="0 0 0"/>
      <geometry>
        <cylinder length="0.11653" radius="0.16459"/>
      </geometry>
    </collision>
  </link>
  <joint name="rear_right_wheel" type="continuous">
    <parent link="base_link"/>
    <child link="rear_right_wheel_link"/>
    <origin rpy="0 0 0" xyz="-0.249 -0.29153 -0.0702"/>
    <axis rpy="0 0 0" xyz="0 1 0"/>
  </joint>
  <!-- Frame -->
  <link name="main_frame_link">
    <visual>
      <origin rpy="0 0 0" xyz="0 0 0"/>
      <geometry>
        <!-- <mesh filename="package://scout_bot_description/meshes/include/Frame.stl"/> -->
      </geometry>
      <material name="dark_grey"/>
    </visual>
    <collision>
      <origin rpy="0 0 0" xyz="0 0 0"/>
      <geometry>
<!--         <mesh filename="package://scout_bot_description/meshes/include/Frame.stl"/>
 -->      </geometry>
    </collision>
  </link>
  <joint name="main_frame_joint" type="fixed">
    <parent link="base_footprint"/>
    <child link="main_frame_link"/>
    <origin rpy="0 0 0" xyz="0 0 0.1349"/>
  </joint>


  <!-- Ouster -->
  <link name="os_sensor">
    <visual>
      <origin rpy="-0.0022 -0.0125 0.0015" xyz="0.5421 0.0020 0.3855"/>
      <geometry>
<!--         <mesh filename="package://scout_bot_description/meshes/lidar/os1_64.dae"/>
 -->      </geometry>
    </visual>
  </link>
  <gazebo reference="os_sensor">
    <sensor name="lidar_3d" type="ray">
      <pose>0 0 0 0 0 0</pose>
      <visualize>false</visualize>
      <update_rate>30</update_rate>
      <ray>
        <scan>
          <horizontal>
            <samples>440</samples>
            <resolution>1</resolution>
            <min_angle>-3.141592653589793</min_angle>
            <max_angle>3.141592653589793</max_angle>
          </horizontal>
          <vertical>
            <samples>16</samples>
            <resolution>1</resolution>
            <min_angle>-0.2617993877991494</min_angle>
            <max_angle>0.2617993877991494</max_angle>
          </vertical>
        </scan>
        <range>
          <min>0.3</min>
          <max>50.0</max>
          <resolution>0.001</resolution>
        </range>
        <noise>
          <type>gaussian</type>
          <mean>0.0</mean>
          <stddev>0.0</stddev>
        </noise>
      </ray>
      <plugin filename="libgazebo_ros_velodyne_laser.so" name="gazebo_ros_laser_controller">
        <topicName>/points_raw</topicName>
        <frameName>base_link</frameName>
        <min_range>0.3</min_range>
        <max_range>50.0</max_range>
        <gaussianNoise>0.008</gaussianNoise>
      </plugin>
    </sensor>
  </gazebo>
  <gazebo reference="os_sensor">
    <sensor name="lidar_2d" type="ray">
      <pose>0 0 0 0 0 0</pose>
      <visualize>false</visualize>
      <update_rate>30</update_rate>
      <ray>
        <scan>
          <horizontal>
            <samples>440</samples>
            <resolution>1</resolution>
            <min_angle>-3.141592653589793</min_angle>
            <max_angle>3.141592653589793</max_angle>
          </horizontal>
        </scan>
        <range>
          <min>0.9</min>
          <max>130.0</max>
          <resolution>0.001</resolution>
        </range>
        <noise>
          <type>gaussian</type>
          <mean>0.0</mean>
          <stddev>0.0</stddev>
        </noise>
      </ray>
      <plugin filename="libgazebo_ros_ray_sensor.so" name="scan">
        <output_type>sensor_msgs/LaserScan</output_type>
        <topicName>/scan</topicName>
        <frameName>os_sensor</frameName>
        <min_range>0.9</min_range>
        <max_range>130.0</max_range>
        <gaussianNoise>0.008</gaussianNoise>
      </plugin>
    </sensor>
  </gazebo>
  <joint name="os_sensor_joint" type="fixed">
    <parent link="base_link"/>
    <child link="os_sensor"/>
    <origin rpy="-0.0022 -0.0125 0.0015" xyz="0.5421 0.0020 0.3855"/>
  </joint>

  <!-- IMU Sensor -->
  <link name="imu_link"/>
  <joint name="imu_joint" type="fixed">
    <parent link="base_link"/>
    <child link="imu_link"/>
    <origin xyz="0 0 0.01" rpy="0 0 0"/>
  </joint>
  <gazebo reference="imu_link">
    <gravity>true</gravity>
    <sensor name="imu_sensor" type="imu">
      <plugin filename="libgazebo_ros_imu_sensor.so" name="imu">
        <topicName>imu_raw</topicName>
        <update_rate>0</update_rate>
        <bodyName>imu_link</bodyName>
        <updateRateHZ>30.0</updateRateHZ>
        <gaussianNoise>0.0</gaussianNoise>
        <xyzOffset>0 0 0</xyzOffset>
        <rpyOffset>0 0 0</rpyOffset>
        <frameName>imu_link</frameName>
        <initialOrientationAsReference>false</initialOrientationAsReference>
      </plugin>
      <always_on>true</always_on>
      <update_rate>100</update_rate>
      <visualize>true</visualize>
      <imu>
        <angular_velocity>
          <x>
            <noise type="gaussian">
              <mean>0.0</mean>
              <stddev>2e-4</stddev>
              <bias_mean>0.0000075</bias_mean>
              <bias_stddev>0.0000008</bias_stddev>
            </noise>
          </x>
          <y>
            <noise type="gaussian">
              <mean>0.0</mean>
              <stddev>2e-4</stddev>
              <bias_mean>0.0000075</bias_mean>
              <bias_stddev>0.0000008</bias_stddev>
            </noise>
          </y>
          <z>
            <noise type="gaussian">
              <mean>0.0</mean>
              <stddev>2e-4</stddev>
              <bias_mean>0.0000075</bias_mean>
              <bias_stddev>0.0000008</bias_stddev>
            </noise>
          </z>
        </angular_velocity>
        <linear_acceleration>
          <x>
            <noise type="gaussian">
              <mean>0.0</mean>
              <stddev>1.7e-2</stddev>
              <bias_mean>0.1</bias_mean>
              <bias_stddev>0.001</bias_stddev>
            </noise>
          </x>
          <y>
            <noise type="gaussian">
              <mean>0.0</mean>
              <stddev>1.7e-2</stddev>
              <bias_mean>0.1</bias_mean>
              <bias_stddev>0.001</bias_stddev>
            </noise>
          </y>
          <z>
            <noise type="gaussian">
              <mean>0.0</mean>
              <stddev>1.7e-2</stddev>
              <bias_mean>0.1</bias_mean>
              <bias_stddev>0.001</bias_stddev>
            </noise>
          </z>
        </linear_acceleration>
      </imu>
    </sensor>
  </gazebo>

  <!-- Sonar 1 (right) -->
  <link name="S2"/>
  <joint name="S2_joint" type="fixed">
    <parent link="base_footprint"/>
    <child link="S2"/>
    <origin rpy="0 0 1.5707963267948966" xyz="0 0.3 0.364"/>
  </joint>
  <!-- Sonar 2 (left) -->
  <link name="S1"/>
  <joint name="S1_joint" type="fixed">
    <parent link="base_footprint"/>
    <child link="S1"/>
    <origin rpy="0 0 -1.5707963267948966" xyz="0 -0.3 0.364"/>
  </joint>
  <!-- Sonar 3 -->
  <link name="S3"/>
  <joint name="S3_joint" type="fixed">
    <parent link="base_footprint"/>
    <child link="S3"/>
    <origin rpy="0 0 -3.141592653589793" xyz="-0.400 0.120 0.364"/>
  </joint>
  <!-- Sonar 4 -->
  <link name="S4"/>
  <joint name="S4_joint" type="fixed">
    <parent link="base_footprint"/>
    <child link="S4"/>
    <origin rpy="0 0 -3.141592653589793" xyz="-0.400 -0.120 0.364"/>
  </joint>
  <!-- Camera 1 -->
  <link name="Cam1"/>
  <joint name="Cam1_joint" type="fixed">
    <parent link="base_link"/>
    <child link="Cam1"/>
    <origin rpy="0 0 0" xyz="0.575 0 0.0945"/>
  </joint>
  <!-- Camera 2 -->
  <link name="Cam2"/>
  <joint name="Cam2_joint" type="fixed">
    <parent link="base_link"/>
    <child link="Cam2"/>
    <origin rpy="0 0 1.5707963267948966" xyz="0 0.303 0.1815"/>
  </joint>
  <!-- Camera 3 -->
  <link name="Cam3"/>
  <joint name="Cam3_joint" type="fixed">
    <parent link="base_link"/>
    <child link="Cam3"/>
    <origin rpy="0 0 -1.5707963267948966" xyz="0 -0.303 0.1815"/>
  </joint>
  <!-- Camera 4 -->
  <link name="Cam4"/>
  <joint name="Cam4_joint" type="fixed">
    <parent link="base_link"/>
    <child link="Cam4"/>
    <origin rpy="0 0 -3.141592653589793" xyz="-0.403 0 0.1295"/>
  </joint>
  <!-- diff_driving setting -->
  <gazebo>
    <plugin filename="libgazebo_ros_diff_drive.so" name="diff_drive">
      <ros>
        <!-- Set namespace -->
        <!-- <namespace>/demo</namespace> -->
        <!-- Remap default topics -->
        <!-- <remapping>cmd_vel:=cmd_demo</remapping>
      <remapping>odom:=odom_demo</remapping> -->
      </ros>
      <!-- Update rate -->
<!--       <update_rate>500</update_rate>
 -->      <!-- Number of wheel pairs -->
      <num_wheel_pairs>2</num_wheel_pairs>
      <!-- wheels0 -->
       
      <left_joint>front_left_wheel</left_joint>
      <right_joint>front_right_wheel</right_joint>
      <!-- wheels1-->
      <left_joint>rear_left_wheel</left_joint>
      <right_joint>rear_right_wheel</right_joint>
      <!-- kinematics -->
      <wheel_separation>0.44</wheel_separation>
      <wheel_separation>0.44</wheel_separation>
      <wheel_diameter>0.2</wheel_diameter>
      <wheel_diameter>0.2</wheel_diameter>
      <!-- limits -->
      <max_wheel_torque>4000</max_wheel_torque>
      <max_wheel_acceleration>1.5</max_wheel_acceleration> 
      <!-- output -->
      <publish_odom>true</publish_odom>
      <publish_odom_tf>false</publish_odom_tf>   <!-- SLAM 시 true -->
      <publish_wheel_tf>true</publish_wheel_tf> <!-- SLAM 시 true -->
      <odometry_frame>odom</odometry_frame>
      <robot_base_frame>base_link</robot_base_frame>
    </plugin>
  </gazebo>
</robot>
